[I 170906 01:53:31 spawnpool:251] Launched [10] new containers.
[I 170906 01:53:31 orchestrate:490] Culling containers unused for 3600 seconds every 600 seconds.
[I 170906 01:53:31 orchestrate:494] Listening on *:9999
[I 170906 01:53:31 orchestrate:498] Admin listening on 127.0.0.1:10000
[I 170906 01:53:40 web:1946] 304 GET / (172.18.0.2) 9.75ms
[I 170906 01:53:41 orchestrate:146] Allocated [/user/oe5WXIAgFK5n/] from the pool.
[I 170906 01:53:41 orchestrate:160] Redirecting [/spawn/] -> [/user/oe5WXIAgFK5n/tree].
[I 170906 01:53:41 web:1946] 302 GET /spawn/ (172.18.0.2) 1.08ms
[I 170906 01:53:41 web:1946] 200 GET /user/oe5WXIAgFK5n/tree (172.18.0.2) 1.48ms
[I 170906 01:53:41 spawnpool:127] Releasing container [PooledContainer(id=026a798c3933fe15278513efdbf1f5468c76eb241270ea1eee9e577e05986076, path=/user/PHXqabqqcyE9/)].
[E 170906 01:53:41 spawnpool:380] Failed to delete route [/user/PHXqabqqcyE9/]: HTTP 599: couldn't connect to host
[E 170906 01:53:51 dockworker:256] Encountered a Docker error with method (5 retries remain): 409 Client Error: Conflict ("b'{"message":"Conflict. The name \\"/tmp.wodeaitensorflow.oe5WXIAgFK5n\\" is already in use by container 71b0e60fe1a83426704b71067cd3734507e083ee4322a72cf46d8d3f33454e40. You have to remove (or rename) that container to be able to reuse that name."}'")
[E 170906 01:53:51 dockworker:256] Encountered a Docker error with method (4 retries remain): 409 Client Error: Conflict ("b'{"message":"Conflict. The name \\"/tmp.wodeaitensorflow.oe5WXIAgFK5n\\" is already in use by container 71b0e60fe1a83426704b71067cd3734507e083ee4322a72cf46d8d3f33454e40. You have to remove (or rename) that container to be able to reuse that name."}'")
[E 170906 01:53:51 dockworker:256] Encountered a Docker error with method (3 retries remain): 409 Client Error: Conflict ("b'{"message":"Conflict. The name \\"/tmp.wodeaitensorflow.oe5WXIAgFK5n\\" is already in use by container 71b0e60fe1a83426704b71067cd3734507e083ee4322a72cf46d8d3f33454e40. You have to remove (or rename) that container to be able to reuse that name."}'")
[E 170906 01:53:51 dockworker:256] Encountered a Docker error with method (2 retries remain): 409 Client Error: Conflict ("b'{"message":"Conflict. The name \\"/tmp.wodeaitensorflow.oe5WXIAgFK5n\\" is already in use by container 71b0e60fe1a83426704b71067cd3734507e083ee4322a72cf46d8d3f33454e40. You have to remove (or rename) that container to be able to reuse that name."}'")
[E 170906 01:53:51 dockworker:256] Encountered a Docker error with method (1 retries remain): 409 Client Error: Conflict ("b'{"message":"Conflict. The name \\"/tmp.wodeaitensorflow.oe5WXIAgFK5n\\" is already in use by container 71b0e60fe1a83426704b71067cd3734507e083ee4322a72cf46d8d3f33454e40. You have to remove (or rename) that container to be able to reuse that name."}'")
[E 170906 01:53:51 dockworker:256] Encountered a Docker error with method (0 retries remain): 409 Client Error: Conflict ("b'{"message":"Conflict. The name \\"/tmp.wodeaitensorflow.oe5WXIAgFK5n\\" is already in use by container 71b0e60fe1a83426704b71067cd3734507e083ee4322a72cf46d8d3f33454e40. You have to remove (or rename) that container to be able to reuse that name."}'")
[E 170906 01:53:51 web:1524] Uncaught exception GET /spawn/user/oe5WXIAgFK5n/tree (172.18.0.2)
    HTTPServerRequest(protocol='http', host='lab.wode.ai', method='GET', uri='/spawn/user/oe5WXIAgFK5n/tree', version='HTTP/1.1', remote_ip='172.18.0.2', headers={'X-Forwarded-Port': '80', 'Accept': 'text/html,application/xhtml+xml,application/xml;q=0.9,image/webp,image/apng,*/*;q=0.8', 'Referer': 'http://lab.wode.ai/user/oe5WXIAgFK5n/tree', 'User-Agent': 'Mozilla/5.0 (Macintosh; Intel Mac OS X 10_12_6) AppleWebKit/537.36 (KHTML, like Gecko) Chrome/60.0.3112.113 Safari/537.36', 'X-Forwarded-For': '::ffff:142.147.58.25', 'Cookie': '_ga=GA1.2.876402153.1504654686; _gid=GA1.2.230385842.1504654686; _gat=1', 'Host': 'lab.wode.ai', 'Accept-Encoding': 'gzip, deflate', 'X-Forwarded-Proto': 'http', 'Accept-Language': 'en-US,en;q=0.8,zh;q=0.6,zh-CN;q=0.4,zh-TW;q=0.2', 'Connection': 'close', 'Upgrade-Insecure-Requests': '1'})
    Traceback (most recent call last):
      File "/usr/local/lib/python3.4/site-packages/docker/client.py", line 142, in _raise_for_status
        response.raise_for_status()
      File "/usr/local/lib/python3.4/site-packages/requests/models.py", line 935, in raise_for_status
        raise HTTPError(http_error_msg, response=self)
    requests.exceptions.HTTPError: 409 Client Error: Conflict for url: http+docker://localunixsocket/v1.24/containers/create?name=tmp.wodeaitensorflow.oe5WXIAgFK5n
    
    During handling of the above exception, another exception occurred:
    
    Traceback (most recent call last):
      File "/usr/local/lib/python3.4/site-packages/tornado/web.py", line 1445, in _execute
        result = yield result
      File "/usr/local/lib/python3.4/site-packages/tornado/gen.py", line 1008, in run
        value = future.result()
      File "/usr/local/lib/python3.4/site-packages/tornado/concurrent.py", line 232, in result
        raise_exc_info(self._exc_info)
      File "<string>", line 3, in raise_exc_info
      File "/usr/local/lib/python3.4/site-packages/tornado/gen.py", line 1014, in run
        yielded = self.gen.throw(*exc_info)
      File "orchestrate.py", line 138, in get
        container = yield self.pool.adhoc(user)
      File "/usr/local/lib/python3.4/site-packages/tornado/gen.py", line 1008, in run
        value = future.result()
      File "/usr/local/lib/python3.4/site-packages/tornado/concurrent.py", line 232, in result
        raise_exc_info(self._exc_info)
      File "<string>", line 3, in raise_exc_info
      File "/usr/local/lib/python3.4/site-packages/tornado/gen.py", line 1014, in run
        yielded = self.gen.throw(*exc_info)
      File "/srv/tmpnb/spawnpool.py", line 115, in adhoc
        launched = yield self._launch_container(user=user, enpool=False)
      File "/usr/local/lib/python3.4/site-packages/tornado/gen.py", line 1008, in run
        value = future.result()
      File "/usr/local/lib/python3.4/site-packages/tornado/concurrent.py", line 232, in result
        raise_exc_info(self._exc_info)
      File "<string>", line 3, in raise_exc_info
      File "/usr/local/lib/python3.4/site-packages/tornado/gen.py", line 1014, in run
        yielded = self.gen.throw(*exc_info)
      File "/srv/tmpnb/spawnpool.py", line 284, in _launch_container
        container_config=self.container_config)
      File "/usr/local/lib/python3.4/site-packages/tornado/gen.py", line 1008, in run
        value = future.result()
      File "/usr/local/lib/python3.4/site-packages/tornado/concurrent.py", line 232, in result
        raise_exc_info(self._exc_info)
      File "<string>", line 3, in raise_exc_info
      File "/usr/local/lib/python3.4/site-packages/tornado/gen.py", line 1014, in run
        yielded = self.gen.throw(*exc_info)
      File "/srv/tmpnb/dockworker.py", line 173, in create_notebook_server
        name=container_name)
      File "/usr/local/lib/python3.4/site-packages/tornado/gen.py", line 1008, in run
        value = future.result()
      File "/usr/local/lib/python3.4/site-packages/tornado/concurrent.py", line 232, in result
        raise_exc_info(self._exc_info)
      File "<string>", line 3, in raise_exc_info
      File "/usr/local/lib/python3.4/site-packages/tornado/gen.py", line 1014, in run
        yielded = self.gen.throw(*exc_info)
      File "/srv/tmpnb/dockworker.py", line 259, in _with_retries
        result = yield self._with_retries(fn, *args, **kwargs)
      File "/usr/local/lib/python3.4/site-packages/tornado/gen.py", line 1008, in run
        value = future.result()
      File "/usr/local/lib/python3.4/site-packages/tornado/concurrent.py", line 232, in result
        raise_exc_info(self._exc_info)
      File "<string>", line 3, in raise_exc_info
      File "/usr/local/lib/python3.4/site-packages/tornado/gen.py", line 1014, in run
        yielded = self.gen.throw(*exc_info)
      File "/srv/tmpnb/dockworker.py", line 259, in _with_retries
        result = yield self._with_retries(fn, *args, **kwargs)
      File "/usr/local/lib/python3.4/site-packages/tornado/gen.py", line 1008, in run
        value = future.result()
      File "/usr/local/lib/python3.4/site-packages/tornado/concurrent.py", line 232, in result
        raise_exc_info(self._exc_info)
      File "<string>", line 3, in raise_exc_info
      File "/usr/local/lib/python3.4/site-packages/tornado/gen.py", line 1014, in run
        yielded = self.gen.throw(*exc_info)
      File "/srv/tmpnb/dockworker.py", line 259, in _with_retries
        result = yield self._with_retries(fn, *args, **kwargs)
      File "/usr/local/lib/python3.4/site-packages/tornado/gen.py", line 1008, in run
        value = future.result()
      File "/usr/local/lib/python3.4/site-packages/tornado/concurrent.py", line 232, in result
        raise_exc_info(self._exc_info)
      File "<string>", line 3, in raise_exc_info
      File "/usr/local/lib/python3.4/site-packages/tornado/gen.py", line 1014, in run
        yielded = self.gen.throw(*exc_info)
      File "/srv/tmpnb/dockworker.py", line 259, in _with_retries
        result = yield self._with_retries(fn, *args, **kwargs)
      File "/usr/local/lib/python3.4/site-packages/tornado/gen.py", line 1008, in run
        value = future.result()
      File "/usr/local/lib/python3.4/site-packages/tornado/concurrent.py", line 232, in result
        raise_exc_info(self._exc_info)
      File "<string>", line 3, in raise_exc_info
      File "/usr/local/lib/python3.4/site-packages/tornado/gen.py", line 1014, in run
        yielded = self.gen.throw(*exc_info)
      File "/srv/tmpnb/dockworker.py", line 259, in _with_retries
        result = yield self._with_retries(fn, *args, **kwargs)
      File "/usr/local/lib/python3.4/site-packages/tornado/gen.py", line 1008, in run
        value = future.result()
      File "/usr/local/lib/python3.4/site-packages/tornado/concurrent.py", line 232, in result
        raise_exc_info(self._exc_info)
      File "<string>", line 3, in raise_exc_info
      File "/usr/local/lib/python3.4/site-packages/tornado/gen.py", line 1014, in run
        yielded = self.gen.throw(*exc_info)
      File "/srv/tmpnb/dockworker.py", line 262, in _with_retries
        raise e
      File "/srv/tmpnb/dockworker.py", line 253, in _with_retries
        result = yield fn(*args, **kwargs)
      File "/usr/local/lib/python3.4/site-packages/tornado/gen.py", line 1008, in run
        value = future.result()
      File "/usr/local/lib/python3.4/concurrent/futures/_base.py", line 395, in result
        return self.__get_result()
      File "/usr/local/lib/python3.4/concurrent/futures/_base.py", line 354, in __get_result
        raise self._exception
      File "/usr/local/lib/python3.4/concurrent/futures/thread.py", line 54, in run
        result = self.fn(*self.args, **self.kwargs)
      File "/usr/local/lib/python3.4/site-packages/docker/api/container.py", line 119, in create_container
        return self.create_container_from_config(config, name)
      File "/usr/local/lib/python3.4/site-packages/docker/api/container.py", line 130, in create_container_from_config
        return self._result(res, True)
      File "/usr/local/lib/python3.4/site-packages/docker/client.py", line 150, in _result
        self._raise_for_status(response)
      File "/usr/local/lib/python3.4/site-packages/docker/client.py", line 146, in _raise_for_status
        raise errors.APIError(e, response, explanation=explanation)
    docker.errors.APIError: 409 Client Error: Conflict ("b'{"message":"Conflict. The name \\"/tmp.wodeaitensorflow.oe5WXIAgFK5n\\" is already in use by container 71b0e60fe1a83426704b71067cd3734507e083ee4322a72cf46d8d3f33454e40. You have to remove (or rename) that container to be able to reuse that name."}'")
[E 170906 01:53:51 web:1946] 500 GET /spawn/user/oe5WXIAgFK5n/tree (172.18.0.2) 10287.67ms